Workbook

Sheet Столы, Тумбы
E1: ИП Киркус Я.Н.
E2: 111123, г.Москва, шоссе Энтузиастов, д.31, стр. 38
E3: тел. +7 (495) 642-70-97
E4: e-mail: 911@riva.ru
E5: www.riva.ru
E7: Измененен: 01.01.2026
A9: Прайс-лист на оперативную мебель серии "STYLE"
A10: ОПИСАНИЕ СЕРИИ
A11: Исполнение: ЛДСП толщиной 22, 18 мм, производство "Kronospan".
A12: Все детали столов, топы/каркасы тумб, приставки, топы/каркасы стеллажей - ЛДСП 22 мм.
A13: Фасады тумб и шкафов - ЛДСП 18 мм.
A15: Цвет металла: Черный, Белый, Антрацит, Серый, Латте, Капучино.
A16: По покраске изделий из металла (от 10 шт) в любой цвет по RAL, обратитесь к вашему менеджеру.
A17: Цвета ЛДСП: Вяз Благородный, Акация Лорка, Белый, Дуб Наварра.
A18: Артикул | B18: Наименование | C18: Размеры Ш*Г*В, (мм) | D18: Изображение | E18: Цена, (руб.)
A19: Л.СП-1 | B19: Стол письменный | C19: 900*720*750 | E19: =Таблица!E4 -> 7056.87
A20: Л.СП-2 | B20: Стол письменный | C20: 1180*720*750 | E20: =Таблица!E5 -> 8187.12
A21: Л.СП-3 | B21: Стол письменный | C21: 1380*720*750 | E21: =Таблица!E6 -> 8804.99
A22: Л.СП-4 | B22: Стол письменный | C22: 1580*720*750 | E22: =Таблица!E7 -> 9644.8
A23: Л.СА-1 Л | B23: Стол криволинейный левый | C23: 1580*900*750 | E23: =Таблица!E8 -> 11360.04
A24: Л.СА-1 Пр | B24: Стол криволинейный правый | C24: 1580*900*750 | E24: =Таблица!E9 -> 11360.04
A25: Л.СА-2 Л | B25: Стол криволинейный левый | C25: 1380*900*750 | E25: =Таблица!E10 -> 10484.61
A26: Л.СА-2 Пр | B26: Стол криволинейный правый | C26: 1380*900*750 | E26: =Таблица!E11 -> 10484.61
A27: Л.СА-3 Л | B27: Стол криволинейный левый | C27: 1380*1200*750 | E27: =Таблица!E12 -> 13935.64
A28: Л.СА-3 Пр | B28: Стол криволинейный правый | C28: 1380*1200*750 | E28: =Таблица!E13 -> 13935.64
A29: Л.СА-4 Л | B29: Стол криволинейный левый | C29: 1580*1200*750 | E29: =Таблица!E14 -> 14700.1
A30: Л.СА-4 Пр | B30: Стол криволинейный правый | C30: 1580*1200*750 | E30: =Таблица!E15 -> 14700.1
A31: Л.ПРГ-2 | B31: Стол переговорный | C31: 1800*900*750 | E31: =Таблица!E16 -> 11264.14
A32: Л.СЖ-1 | B32: Стол журнальный круглый | C32: 600*600*450 | E32: =Таблица!E147 -> 11210.71
A33: Л.СЖ-2 | B33: Стол журнальный квадратный | C33: 600*600*450 | E33: =Таблица!E148 -> 11949.14
A34: Л.СПРГ-1 | B34: Стол круглый | C34: 900*900*750 | E34: =Таблица!E149 -> 17894.94
A35: Л.СПРГ-2 | B35: Стол квадратный | C35: 900*900*750 | E35: =Таблица!E150 -> 19153.97
A36: Л.СПРГ-3 | B36: Стол овальный | C36: 1800*900*750 | E36: =Таблица!E151 -> 35543.28
A37: Л.СПРГ-4 | B37: Стол прямоугольный | C37: 1800*900*750 | E37: =Таблица!E152 -> 38022.98
A38: Л.ТМ-3F | B38: Тумба подкатная (3 ящика фолдинг, с замком) | C38: 420*450*563 | E38: =Таблица!E17 -> 8744.71
A39: Л.ТМ-4F | B39: Тумба подкатная (4 ящика фолдинг, с замком) | C39: 420*450*714 | E39: =Таблица!E18 -> 10277.74
A40: Л.ТП-4F | B40: Тумба приставная (3 ящика фолдинг, с замком) | C40: 420*450*750 | E40: =Таблица!E19 -> 12328.63
A41: Л.ТП-4.1F | B41: Тумба приставная (3 ящика фолдинг, с замком) | C41: 420*600*750 | E41: =Таблица!E20 -> 13531.49
A42: Л.ТП-4.2F | B42: Тумба приставная (3 ящика фолдинг, с замком) | C42: 420*720*750 | E42: =Таблица!E21 -> 13602.73
A43: Л.ТМ-1 | B43: Тумба под оргтехнику сервисная | C43: 770*600*685 | E43: =Таблица!E22 -> 10246.23

Sheet Шкафы
A1: Прайс-лист на оперативную мебель серии "STYLE"
D2: ='Столы, Тумбы'!E7 -> Измененен: 01.01.2026
A3: Артикул | B3: Наименование | C3: Размеры Ш*Г*В (мм) | D3: Изображение | E3: Цена (руб.)
A4: Л.СТ-1 | B4: Стеллаж высокий широкий | C4: 778*410*1980 | E4: =Таблица!E23 -> 11232.63
A5: Л.СТ-2 | B5: Стеллаж средний широкий | C5: 778*410*1215 | E5: =Таблица!E24 -> 8222.74
A6: Л.СТ-3 | B6: Стеллаж низкий широкий | C6: 778*410*828 | E6: =Таблица!E25 -> 6206.1
A7: Л.СУ-1 | B7: Стеллаж высокий узкий | C7: 412*410*1980 | E7: =Таблица!E26 -> 9147.49
A8: Л.СУ-2 | B8: Стеллаж средний узкий | C8: 412*410*1215 | E8: =Таблица!E27 -> 6081.43
A9: Л.СУ-3 | B9: Стеллаж низкий узкий | C9: 412*410*828 | E9: =Таблица!E28 -> 4427.84
A10: Л.ГБ-1 | B10: Гардероб узкий (выдвижная вешалка, левое открывание) | C10: 558*410*1980 | E10: =Таблица!E29 -> 12291.64
A11: Л.ГБ-2 | B11: Гардероб глубокий (вешалка-штанга) | C11: 778*580*1980 | E11: =Таблица!E30 -> 18642.96
A12: Л.ГБ-4 | B12: Гардероб комбинированный (выдвижная вешалка) | C12: 778*410*1980 | E12: =Таблица!E31 -> 21559.69
A13: Л.СТ-1.1 | B13: Шкаф высокий широкий (2 низкие двери ЛДСП) | C13: 778*410*1980 | E13: =Таблица!E32 -> 14676.81
A14: Л.СТ-1.2 | B14: Шкаф высокий широкий (2 низкие двери ЛДСП, 2 средние двери стекло) | C14: 778*410*1980 | E14: =Таблица!E33 -> 21211.71
A15: Л.СТ-1.3 | B15: Шкаф высокий широкий (2 низкие двери ЛДСП, 2 средние двери ЛДСП) | C15: 778*410*1980 | E15: =Таблица!E34 -> 18838.87
... A26: Л.СУ-1.1 Л/Пр | B26: Шкаф высокий узкий левый/правый (1 низкая дверь ЛДСП) | C26: 412*410*1980 | E26: =Таблица!E45 -> 10869.58
A27: Л.СУ-1.2 Л/Пр | B27: Шкаф высокий узкий левый/правый (1 низкая дверь ЛДСП, 1 средняя дверь стекло) | C27: 412*410*1980 | E27: =Таблица!E47 -> 14137.03
A28: Л.СУ-1.3 Л/Пр | B28: Шкаф высокий узкий левый/правый (1 низкая дверь ЛДСП, 1 средняя дверь ЛДСП) | C28: 412*410*1980 | E28: =Таблица!E49 -> 12950.61
A29: Л.СУ-1.4 Л/Пр | B29: Шкаф высокий узкий левый/правый (1 низкая дверь ЛДСП, 1 низкая дверь стекло) | C29: 412*410*1980 | E29: =Таблица!E51 -> 13684.93
A30: Л.СУ-1.5 Л/Пр | B30: Шкаф высокий узкий левый/правый (2 низкие двери ЛДСП) | C30: 412*410*1980 | E30: =Таблица!E53 -> 12591.67
A31: Л.СУ-1.6Л/Пр | B31: Шкаф высокий узкий левый/правый (1 средняя дверь ЛДСП) | C31: 412*410*1980 | E31: =Таблица!E55 -> 11228.52
A32: Л.СУ-1.7 Л/Пр | B32: Шкаф высокий узкий левый/правый (1 средняя дверь ЛДСП, 1 низкая дверь стекло) | C32: 412*410*1980 | E32: =Таблица!E57 -> 14043.87
A33: Л.СУ-1.8 Л/Пр | B33: Шкаф высокий узкий левый/правый (1 средняя дверь ЛДСП, 1 низкая дверь ЛДСП) | C33: 412*410*1980 | E33: =Таблица!E59 -> 12950.61
A34: Л.СУ-1.9 Л/Пр | B34: Шкаф высокий узкий левый/правый (1 высокая дверь ЛДСП) | C34: 412*410*1980 | E34: =Таблица!E61 -> 12213.55
A35: Л.СТ-2.1 | B35: Шкаф средний широкий (2 низкие двери ЛДСП) | C35: 778*410*1215 | E35: =Таблица!E63 -> 11666.92
A36: Л.СТ-2.2 | B36: Шкаф средний широкий (2 низкие двери стекло) | C36: 778*410*1215 | E36: =Таблица!E64 -> 13853.44
A37: Л.СТ-2.3 | B37: Шкаф средний широкий (2 средние двери ЛДСП) | C37: 778*410*1215 | E37: =Таблица!E65 -> 12384.8
A38: Л.СТ-2.4 | B38: Шкаф средний широкий (2 средние двери стекло) | C38: 778*410*1215 | E38: =Таблица!E66 -> 14757.64
A39: Л.СУ-2.1 Л/Пр | B39: Шкаф средний узкий левый/правый (1 низкая дверь ЛДСП) | C39: 412*410*1215 | E39: =Таблица!E67 -> 7803.52
A40: Л.СУ-2.2 Л/Пр | B40: Шкаф средний узкий левый/правый (1 низкая дверь стекло) | C40: 412*410*1215 | E40: =Таблица!E69 -> 8896.78
A41: Л.СУ-2.3 Л/Пр | B41: Шкаф средний узкий левый/правый (1 средняя дверь ЛДСП) | C41: 412*410*1215 | E41: =Таблица!E71 -> 8162.46
A42: Л.СУ-2.4 Л/Пр | B42: Шкаф средний узкий левый/правый (1 средняя дверь стекло) | C42: 412*410*1215 | E42: =Таблица!E73 -> 9348.88
A43: Л.СТ-3.1 | B43: Шкаф низкий широкий (2 низкие двери ЛДСП) | C43: 778*410*828 | E43: =Таблица!E75 -> 9650.28
A44: Л.СТ-3.2 | B44: Шкаф низкий широкий (2 низкие двери стекло) | C44: 778*410*828 | E44: =Таблица!E76 -> 11836.8
A45: Л.СУ-3.1 Л/Пр | B45: Шкаф низкий узкий левый/правый (1 низкая дверь ЛДСП) | C45: 412*410*828 | E45: =Таблица!E77 -> 6149.93
A46: Л.СУ-3.2 Л/Пр | B46: Шкаф низкий узкий левый/правый (1 низкая дверь стекло) | C46: 412*410*828 | E46: =Таблица!E79 -> 7243.19

Sheet Аксессуары
A1: Прайс-лист на оперативную мебель серии "STYLE"
D2: ='Столы, Тумбы'!E7 -> Измененен: 01.01.2026
A3: Артикул | B3: Наименование | C3: Размеры Ш*Г*В, (мм) | D3: Изображение | E3: Цена, (руб.)
A4: Л.ПР-2 | B4: Приставка | C4: 720*402*22 | E4: =Таблица!E81 -> 2663.28
A5: Л.ПР-2.1 | B5: Приставка | C5: 600*400*22 | E5: =Таблица!E82 -> 2292.01
A6: Л.ПР-3 | B6: Приставка | C6: 720*720*22 | E6: =Таблица!E83 -> 2797.54
A7: Л.ПР-4 | B7: Приставка | C7: 600*600*22 | E7: =Таблица!E84 -> 2193.37
A8: Л.ПР-5 | B8: Приставка | C8: 600*720*22 | E8: =Таблица!E85 -> 2629.03
A9: Л.ПР-6 | B9: Приставка | C9: 1200*600*22 | E9: =Таблица!E86 -> 3868.88
A10: Л.ПР-7 | B10: Приставка | C10: 1440*720*22 | E10: =Таблица!E87 -> 5637.55
A11: Л.ПР-8 | B11: Приставка | C11: 1225*610*22 | E11: =Таблица!E88 -> 3953.82
A12: Л.ПР-9 | B12: Приставка | C12: 1465*730*22 | E12: =Таблица!E89 -> 5777.29
A13: Л.ПР-10 | B13: Приставка | C13: 900*452*22 | E13: =Таблица!E90 -> 3845.59
A14: А.ВТ-710 | B14: Опора металлическая (хром) | C14: 60*60*710 | E14: =Таблица!E91 -> 1560.43
A15: Л.ПНС-1 | B15: Полка навесная | C15: 1000*336*540 | E15: =Таблица!E92 -> 4842.95
... A17: Л.НС-3 | B17: Надставка на стол | C17: 1440*300*420 | E17: =Таблица!E94 -> 3929.16
A18: KKV | B18: Кабель-канал вертикальный (цвет - серебристый металлик) | C18: L = 780 мм | E18: =Таблица!E182 -> 2096.1
A19: Л.СБ-1 | B19: Подставка под системный блок | C19: 284*450*342 | E19: =Таблица!E105 -> 2692.05
A20: PM-LBFI60-05 | B20: Заглушка кабель-канала "Люкс" | C20: D-60 | E20: =Таблица!E106 -> 468.54
A21: Я3-2R/4С | B21: Ящик для стекол (4 низкие двери стекло) | E21: =Таблица!E107 -> 391.82
A22: Я3-6R/10С | B22: Ящик для стекол (10 низких дверей стекло) | E22: =Таблица!E108 -> 476.76
A23: Я2-2R/4С | B23: Ящик для стекол (4 средние двери стекло) | E23: =Таблица!E109 -> 543.89
A24: Я2-6R/10С | B24: Ящик для стекол (10 средних дверей стекло) | E24: =Таблица!E110 -> 630.2

Sheet Ресепшн
A1: Стойка-ресепшн "STYLE"
D2: ='Столы, Тумбы'!E7 -> Измененен: 01.01.2026
A3: Исполнение: ЛДСП толщиной 18, 22, 36 мм, производство - "Kronospan".
A4: Гостевая столешница - ЛДСП толщиной 36 мм.
A5: Рабочая столешница и боковины - ЛДСП толщиной 22 мм.
A6: Остальные детали изделий - ЛДСП толщиной 18 мм.
A7: Цвета: Вяз Благородный/Белый; Акация Лорка/Белый; Дуб Наварра/Белый.
A8: Артикул | B8: Наименование | C8: Размеры Ш*Г*В, (мм) | D8: Изображение | E8: Цена, (руб.)
A9: Л.МП-1 | B9: Модуль прямой | C9: 800*736*1156 | E9: =Таблица!E125 -> 11013.43
A10: Л.МП-2 | B10: Модуль прямой | C10: 1000*736*1156 | E10: =Таблица!E126 -> 12698.53
A11: Л.МП-3 | B11: Модуль прямой | C11: 1200*736*1156 | E11: =Таблица!E127 -> 14538.44
A12: Л.МП-4 | B12: Модуль прямой | C12: 1400*736*1156 | E12: =Таблица!E128 -> 16182.44
A13: Л.МП-5 | B13: Модуль прямой | C13: 1600*736*1156 | E13: =Таблица!E129 -> 18367.59
A14: Л.УМ-1 Л | B14: Угловой модуль левый | C14: 736*736*1156 | E14: =Таблица!E130 -> 18538.84
A15: Л.УМ-1 Пр | B15: Угловой модуль правый | C15: 736*736*1156 | E15: =Таблица!E131 -> 18538.84
A16: Л.Б Л | B16: Боковина левая | C16: 741*22*1159 | E16: =Таблица!E132 -> 4182.61
A17: Л.Б Пр | B17: Боковина правая | C17: 741*22*1159 | E17: =Таблица!E133 -> 4182.61
A18: Л.БУ Л | B18: Боковина узкая левая | C18: 305*22*1159 | E18: =Таблица!E134 -> 1960.47
A19: Л.БУ Пр | B19: Боковина узкая правая | C19: 305*22*1159 | E19: =Таблица!E135 -> 1960.47
A20: Л.Н-1 | B20: Накладка для Л.МП-1 | C20: 360*321*536 | E20: =Таблица!E136 -> 2676.98
... A30: ОБ-76 | B30: Опора металлическая (цвет - Черный, Белый, Антрацит, Серый, Латте, Капучино) | C30: D = 76 мм; H = 728 мм | E30: =Таблица!E146 -> 3634.61

Sheet Ресепшен наборы
A1: Стойка-ресепшн "STYLE"
D2: ='Столы, Тумбы'!E7 -> Измененен: 01.01.2026
A3: Исполнение: ЛДСП толщиной 18, 22, 36 мм, производство - "Kronospan".
A4: Гостевая столешница - ЛДСП толщиной 36 мм.
A5: Рабочая столешница и боковины - ЛДСП толщиной 22 мм.
A6: Остальные детали изделий - ЛДСП толщиной 18 мм.
A7: Цвета: Вяз Благородный/Белый; Акация Лорка/Белый; Дуб Наварра/Белый.
A8: Артикул | B8: Наименование | C8: Размеры Ш*Г*В, (мм) | D8: Изображение | E8: Цена, (руб.)
A9: Л.РН-1 | B9: Набор вариант №1 | C9: 1044*736*1156 | E9: =Таблица!E184 -> 27162.99
A10: Л.РН-2 | B10: Набор вариант №2 | C10: 2472*736*1156 | E10: =Таблица!E185 -> 92265.39
A11: Л.РН-3 | B11: Набор вариант №3 | C11: 2044*1758*1156 | E11: =Таблица!E186 -> 37396.89
A12: Л.РН-4 | B12: Набор вариант №4 | C12: 1758*1758*1156 | E12: =Таблица!E187 -> 55935.73
A13: Л.РН-5 | B13: Набор вариант №5 | C13: 2472*758*1156 | E13: =Таблица!E188 -> 60966.37

Sheet Сборные элементы
A1: Прайс-лист на оперативную мебель серии "STYLE"
D2: ='Столы, Тумбы'!E7 -> Измененен: 01.01.2026
A3: Артикул | B3: Наименование | C3: Размеры Ш*Г*В, (мм) | D3: Изображение | E3: Цена, (руб.)
A4: Л.ГБ-2К | B4: Каркас гардероба Л.ГБ-2 | C4: 778*580*1980 | E4: =Таблица!E111 -> 12510.84
A5: Л.ГБ-4К | B5: Каркас гардероба Л.ГБ-4К | C5: 778*410*1980 | E5: =Таблица!E112 -> 15427.57
A6: Л.Д-1 Л/Пр | B6: Дверь высокая ЛДСП левая/правая (для Л.ГБ-2, Л.СТ-1, Л.СУ-1 и Л.ГБ-4) | C6: 361*1916*18 | E6: =Таблица!E113 -> 3066.06
A7: Л.Д-2 Л/Пр | B7: Дверь средняя ЛДСП левая/правая (для Л.СТ-1, Л.СУ-1, Л.СТ-2, Л.СУ-2) | C7: 361*1151*18 | E7: =Таблица!E115 -> 2081.03
A8: Л.Д-3 Л/Пр | B8: Дверь низкая ЛДСП левая/правая (для Л.СТ-1, Л.СУ-1, Л.СТ-2, Л.СТ-3, Л.СУ-2, Л.СУ-3) | C8: 361*764*18 | E8: =Таблица!E117 -> 1722.09
A9: Л.С-2 | B9: Дверь средняя стекло (для Л.СТ-1, Л.СУ-1, Л.СТ-2, Л.СУ-2) | C9: 361*1151*4 | E9: =Таблица!E119 -> 2438.6
A10: Л.С-3 | B10: Дверь низкая стекло (для Л.СТ-1, Л.СТ-2, Л.СТ-3, Л.СУ-1, Л.СУ-2, Л.СУ-3) | C10: 361*764*4 | E10: =Таблица!E121 -> 1986.5
A11: Для Л.С-2 | B11: Комплект фурнитуры для одного стекла | E11: =Таблица!E123 -> 828.85
A12: Для Л.С-3 | B12: Комплект фурнитуры для одного стекла | E12: =Таблица!E124 -> 828.85

Sheet Таблица
G2: Коэффициент
A3: Артикул | B3: Наименование | C3: Размеры Ш*Г*В (мм) | D3: Цена (руб.) | E3: Цена с учетом коэффициента (руб.) | G3: 1.37 | I3: Артикул | J3: Наименование ЭЛЕМЕНТА №1 | K3: Размер | L3: Кол-во | M3: Цена | O3: Артикул | P3: Наименование ЭЛЕМЕНТА №2 | Q3: Размер | R3: Кол-во | S3: Цена | U3: Артикул | V3: Наименование ЭЛЕМЕНТА №3 | W3: Размер | X3: Кол-во | Y3: Цена | AA3: Артикул | AB3: Наименование ЭЛЕМЕНТА №4 | AC3: Размер | AD3: Кол-во | AE3: Цена | AG3: Артикул | AH3: Наименование ЭЛЕМЕНТА №5 | AI3: Размер | AJ3: Кол-во | AK3: Цена | AM3: Артикул | AN3: Наименование ЭЛЕМЕНТА №6 | AO3: Размер | AP3: Кол-во | AQ3: Цена
A4: Л.СП-1 | B4: Стол письменный | C4: 900*720*750 | D4: 5151 | E4: =D4*$G$3 -> 7056.87 | F4: УТ-00001533
A5: Л.СП-2 | B5: Стол письменный | C5: 1180*720*750 | D5: 5976 | E5: =D5*$G$3 -> 8187.12 | F5: УТ-00001534
A6: Л.СП-3 | B6: Стол письменный | C6: 1380*720*750 | D6: 6427 | E6: =D6*$G$3 -> 8804.99 | F6: УТ-00001531
A7: Л.СП-4 | B7: Стол письменный | C7: 1580*720*750 | D7: 7040 | E7: =D7*$G$3 -> 9644.8 | F7: УТ-00001535
A8: Л.СА-1 (L) | B8: Стол криволинейный левый | C8: 1580*900*750 | D8: 8292 | E8: =D8*$G$3 -> 11360.04 | F8: УТ-00001536
A9: Л.СА-1 (R) | B9: Стол криволинейный правый | C9: 1580*900*750 | D9: 8292 | E9: =D9*$G$3 -> 11360.04 | F9: УТ-00001537
A10: Л.СА-2 (L) | B10: Стол криволинейный левый | C10: 1380*900*750 | D10: 7653 | E10: =D10*$G$3 -> 10484.61 | F10: УТ-00001482
A11: Л.СА-2 (R) | B11: Стол криволинейный правый | C11: 1380*900*750 | D11: 7653 | E11: =D11*$G$3 -> 10484.61 | F11: УТ-00001521
A12: Л.СА-3 (L) | B12: Стол криволинейный левый | C12: 1380*1200*750 | D12: 10172 | E12: =D12*$G$3 -> 13935.64 | F12: УТ-00001538
A13: Л.СА-3 (R) | B13: Стол криволинейный правый | C13: 1380*1200*750 | D13: 10172 | E13: =D13*$G$3 -> 13935.64 | F13: УТ-00001539
A14: Л.СА-4 (L) | B14: Стол криволинейный левый | C14: 1580*1200*750 | D14: 10730 | E14: =D14*$G$3 -> 14700.1 | F14: УТ-00001540
A15: Л.СА-4 (R) | B15: Стол криволинейный правый | C15: 1580*1200*750 | D15: 10730 | E15: =D15*$G$3 -> 14700.1 | F15: УТ-00001541
A16: Л.ПРГ-2 | B16: Стол переговорный | C16: 1800*900*750 | D16: 8222 | E16: =D16*$G$3 -> 11264.14 | F16: УТ-00001542
A17: Л.ТМ-3F | B17: Тумба подкатная (3 ящика фолдинг, с замком) | C17: 420*450*563 | D17: 6383 | E17: =D17*$G$3 -> 8744.71 | F17: ЦБ-00032906 | I17: =A153 -> Л.ТМ-3F | J17: =B153 -> Тумба подкатная 3 ящ. без фолдинга | K17: =C153 -> 420*450*563 | L17: 1 | M17: =D153 -> 5463 | O17: =A154 -> Ф1248 | P17: =B154 -> Комплект Фолдинг Ф1248 (на 3 ящика) | Q17: =C154 -> 400*347*100 | R17: 1 | S17: =D154 -> 920
A18: Л.ТМ-4F | B18: Тумба подкатная (4 ящика фолдинг, с замком) | C18: 420*450*714 | D18: 7502 | E18: =D18*$G$3 -> 10277.74 | F18: ЦБ-00032909 | I18: =A155 -> Л.ТМ-4F | J18: =B155 -> Тумба подкатная 4 ящ. без фолдинга | K18: =C155 -> 420*450*714 | L18: 1 | M18: =D155 -> 6319 | O18: =A156 -> Ф1249 | P18: =B156 -> Комплект Фолдинг Ф1249 (на 4 ящика) | Q18: =C156 -> 400*347*100 | R18: 1 | S18: =D156 -> 1183
A19: Л.ТП-4F | B19: Тумба приставная (3 ящика фолдинг, с замком) | C19: 420*450*750 | D19: 8999 | E19: =D19*$G$3 -> 12328.63 | F19: ЦБ-00032912 | I19: =A157 -> Л.ТП-4F | J19: =B157 -> Тумба приставная без фолдинга | K19: =C157 -> 420*450*750 | L19: 1 | M19: =D157 -> 8079 | O19: =A154 -> Ф1248 | P19: =B154 -> Комплект Фолдинг Ф1248 (на 3 ящика) | Q19: =C154 -> 400*347*100 | R19: 1 | S19: =D154 -> 920
A20: Л.ТП-4.1F | B20: Тумба приставная (3 ящика фолдинг, с замком) | C20: 420*600*750 | D20: 9877 | E20: =D20*$G$3 -> 13531.49 | F20: ЦБ-00032914 | I20: =A158 -> Л.ТП-4.1F | J20: =B158 -> Тумба приставная без фолдинга | K20: =C158 -> 420*600*750 | L20: 1 | M20: =D158 -> 8957 | O20: =A154 -> Ф1248 | P20: =B154 -> Комплект Фолдинг Ф1248 (на 3 ящика) | Q20: =C154 -> 400*347*100 | R20: 1 | S20: =D154 -> 920
A21: Л.ТП-4.2F | B21: Тумба приставная (3 ящика фолдинг, с замком) | C21: 420*720*750 | D21: 9929 | E21: =D21*$G$3 -> 13602.73 | F21: ЦБ-00032916 | I21: =A159 -> Л.ТП-4.2F | J21: =B159 -> Тумба приставная без фолдинга | K21: =C159 -> 420*720*750 | L21: 1 | M21: =D159 -> 9009 | O21: =A154 -> Ф1248 | P21: =B154 -> Комплект Фолдинг Ф1248 (на 3 ящика) | Q21: =C154 -> 400*347*100 | R21: 1 | S21: =D154 -> 920
A22: Л.ТМ-1 | B22: Тумба под оргтехнику сервисная | C22: 770*600*685 | D22: 7479 | E22: =D22*$G$3 -> 10246.23 | F22: УТ-00001568
A23: Л.СТ-1 | B23: Стеллаж высокий широкий | C23: 778*410*1980 | D23: 8199 | E23: =D23*$G$3 -> 11232.63 | F23: ЦБ-00007032
A24: Л.СТ-2 | B24: Стеллаж средний широкий | C24: 778*410*1215 | D24: 6002 | E24: =D24*$G$3 -> 8222.74 | F24: УТ-00001563
A25: Л.СТ-3 | B25: Стеллаж низкий широкий | C25: 778*410*828 | D25: 4530 | E25: =D25*$G$3 -> 6206.1 | F25: УТ-00001566
A26: Л.СУ-1 | B26: Стеллаж высокий узкий | C26: 412*410*1980 | D26: 6677 | E26: =D26*$G$3 -> 9147.49 | F26: УТ-00001561
A27: Л.СУ-2 | B27: Стеллаж средний узкий | C27: 412*410*1215 | D27: 4439 | E27: =D27*$G$3 -> 6081.43 | F27: УТ-00001565
A28: Л.СУ-3 | B28: Стеллаж низкий узкий | C28: 412*410*828 | D28: 3232 | E28: =D28*$G$3 -> 4427.84 | F28: УТ-00001567
A29: Л.ГБ-1 | B29: Гардероб узкий (выдвижная вешалка) | C29: 558*410*1980 | D29: 8972 | E29: =D29*$G$3 -> 12291.64 | F29: ЦБ-00003116
A30: Л.ГБ-2 | B30: Гардероб глубокий(вешалка-штанга) | C30: 778*580*1980 | D30: 13608 | E30: =D30*$G$3 -> 18642.96 | F30: ЦБ-00013106 | I30: =A111 -> Л.ГБ-2К | J30: =B111 -> Каркас гардероба Л.ГБ-2 | K30: =C111 -> 778*580*1980 | L30: 1 | M30: =D111 -> 9132 | O30: =A113 -> Л.Д-1 (L) | P30: =B113 -> Дверь высокая ЛДСП левая/правая (для Л.ГБ-2, Л.СТ-1, Л.СУ-1 и Л.ГБ-4) | Q30: =C113 -> 361*1916x18 | R30: 1 | S30: =D113 -> 2238 | U30: =A114 -> Л.Д-1 (R) | V30: =B114 -> Дверь высокая ЛДСП левая/правая (для Л.ГБ-2, Л.СТ-1, Л.СУ-1 и Л.ГБ-4) | W30: =C114 -> 361*1916x18 | X30: 1 | Y30: =D114 -> 2238
A31: Л.ГБ-4 | B31: Гардероб комбинированный (выдвижная вешалка) | C31: 778*410*1980 | D31: 15737 | E31: =D31*$G$3 -> 21559.69 | F31: ЦБ-00013107 | I31: =A112 -> Л.ГБ-4К | J31: =B112 -> Каркас гардероба Л.ГБ-4К | K31: =C112 -> 778*410*1980 | L31: 1 | M31: =D112 -> 11261 | O31: =A113 -> Л.Д-1 (L) | P31: =B113 -> Дверь высокая ЛДСП левая/правая (для Л.ГБ-2, Л.СТ-1, Л.СУ-1 и Л.ГБ-4) | Q31: =C113 -> 361*1916x18 | R31: 1 | S31: =D113 -> 2238 | U31: =A114 -> Л.Д-1 (R) | V31: =B114 -> Дверь высокая ЛДСП левая/правая (для Л.ГБ-2, Л.СТ-1, Л.СУ-1 и Л.ГБ-4) | W31: =C114 -> 361*1916x18 | X31: 1 | Y31: =D114 -> 2238
A32: Л.СТ-1.1 | B32: Шкаф высокий широкий (2 низкие двери ЛДСП) | C32: 778*410*1980 | D32: 10713 | E32: =D32*$G$3 -> 14676.81 | F32: ЦБ-00013108 | I32: =A23 -> Л.СТ-1 | J32: =B23 -> Стеллаж высокий широкий | K32: =C23 -> 778*410*1980 | L32: 1 | M32: =D23 -> 8199 | O32: =A117 -> Л.Д-3 (L) | P32: =B117 -> Дверь низкая ЛДСП (для Л.СТ-1, Л.СУ-1, Л.СТ-2, Л.СТ-3, Л.СУ-2, Л.СУ-3) | Q32: =C117 -> 361*764x18 | R32: 1 | S32: =D117 -> 1257 | U32: =A118 -> Л.Д-3 (R) | V32: =B118 -> Дверь низкая ЛДСП (для Л.СТ-1, Л.СУ-1, Л.СТ-2, Л.СТ-3, Л.СУ-2, Л.СУ-3) | W32: =C118 -> 361*764x18 | X32: 1 | Y32: =D118 -> 1257
A33: Л.СТ-1.2 | B33: Шкаф высокий широкий (2 низкие двери ЛДСП, 2 средние двери стекло) | C33: 778*410*1980 | D33: 15483 | E33: =D33*$G$3 -> 21211.71 | F33: ЦБ-00013109 | I33: =A23 -> Л.СТ-1 | J33: =B23 -> Стеллаж высокий широкий | K33: =C23 -> 778*410*1980 | L33: 1 | M33: =D23 -> 8199 | O33: =A117 -> Л.Д-3 (L) | P33: =B117 -> Дверь низкая ЛДСП (для Л.СТ-1, Л.СУ-1, Л.СТ-2, Л.СТ-3, Л.СУ-2, Л.СУ-3) | Q33: =C117 -> 361*764x18 | R33: 1 | S33: =D117 -> 1257 | U33: =A118 -> Л.Д-3 (R) | V33: =B118 -> Дверь низкая ЛДСП (для Л.СТ-1, Л.СУ-1, Л.СТ-2, Л.СТ-3, Л.СУ-2, Л.СУ-3) | W33: =C118 -> 361*764x18 | X33: 1 | Y33: =D118 -> 1257 | AA33: =A119 -> Л.С-2 (L) | AB33: =B119 -> Дверь средняя стекло (для Л.СТ-1, Л.СУ-1, Л.СТ-2, Л.СУ-2) | AC33: =C119 -> 361*1151x4 | AD33: 1 | AE33: =D119 -> 1780 | AG33: =A120 -> Л.С-2 (R) | AH33: =B120 -> Дверь средняя стекло (для Л.СТ-1, Л.СУ-1, Л.СТ-2, Л.СУ-2) | AI33: =C120 -> 361*1151x4 | AJ33: 1 | AK33: =D120 -> 1780 | AM33: =A123 -> Для Л.С-2 | AN33: =B123 -> Комплект фурнитуры для одного стекла | AP33: 2 | AQ33: =D123 -> 605
A34: Л.СТ-1.3 | B34: Шкаф высокий широкий (2 низкие двери ЛДСП, 2 средние двери ЛДСП) | C34: 778*410*1980 | D34: 13751 | E34: =D34*$G$3 -> 18838.87 | F34: ЦБ-00013110 | I34: =A23 -> Л.СТ-1 | J34: =B23 -> Стеллаж высокий широкий | K34: =C23 -> 778*410*1980 | L34: 1 | M34: =D23 -> 8199 | O34: =A115 -> Л.Д-2 (L) | P34: =B115 -> Дверь средняя ЛДСП (для Л.СТ-1, Л.СУ-1, Л.СТ-2, Л.СУ-2) | Q34: =C115 -> 361*1151x18 | R34: 1 | S34: =D115 -> 1519 | U34: =A116 -> Л.Д-2 (R) | V34: =B116 -> Дверь средняя ЛДСП (для Л.СТ-1, Л.СУ-1, Л.СТ-2, Л.СУ-2) | W34: =C116 -> 361*1151x18 | X34: 1 | Y34: =D116 -> 1519 | AA34: =A117 -> Л.Д-3 (L) | AB34: =B117 -> Дверь низкая ЛДСП (для Л.СТ-1, Л.СУ-1, Л.СТ-2, Л.СТ-3, Л.СУ-2, Л.СУ-3) | AC34: =C117 -> 361*764x18 | AD34: 1 | AE34: =D117 -> 1257 | AG34: =A118 -> Л.Д-3 (R) | AH34: =B118 -> Дверь низкая ЛДСП (для Л.СТ-1, Л.СУ-1, Л.СТ-2, Л.СТ-3, Л.СУ-2, Л.СУ-3) | AI34: =C118 -> 361*764x18 | AJ34: 1 | AK34: =D118 -> 1257
A35: Л.СТ-1.4 | B35: Шкаф высокий широкий (2 низкие двери ЛДСП, 2 низкие двери стекло) | C35: 778*410*1980 | D35: 14823 | E35: =D35*$G$3 -> 20307.51 | F35: ЦБ-00013111 | I35: =A23 -> Л.СТ-1 | J35: =B23 -> Стеллаж высокий широкий | K35: =C23 -> 778*410*1980 | L35: 1 | M35: =D23 -> 8199 | O35: =A117 -> Л.Д-3 (L) | P35: =B117 -> Дверь низкая ЛДСП (для Л.СТ-1, Л.СУ-1, Л.СТ-2, Л.СТ-3, Л.СУ-2, Л.СУ-3) | Q35: =C117 -> 361*764x18 | R35: 1 | S35: =D117 -> 1257 | U35: =A118 -> Л.Д-3 (R) | V35: =B118 -> Дверь низкая ЛДСП (для Л.СТ-1, Л.СУ-1, Л.СТ-2, Л.СТ-3, Л.СУ-2, Л.СУ-3) | W35: =C118 -> 361*764x18 | X35: 1 | Y35: =D118 -> 1257 | AA35: =A121 -> Л.С-3 (L) | AB35: =B121 -> Дверь низкая стекло (для Л.СТ-1, Л.СТ-2, Л.СТ-3, Л.СУ-1, Л.СУ-2, Л.СУ-3) | AC35: =C121 -> 361*764x4 | AD35: 1 | AE35: =D121 -> 1450 | AG35: =A122 -> Л.С-3 (R) | AH35: =B122 -> Дверь низкая стекло (для Л.СТ-1, Л.СТ-2, Л.СТ-3, Л.СУ-1, Л.СУ-2, Л.СУ-3) | AI35: =C122 -> 361*764x4 | AJ35: 1 | AK35: =D122 -> 1450 | AM35: =A123 -> Для Л.С-2 | AN35: =B123 -> Комплект фурнитуры для одного стекла | AP35: 2 | AQ35: =D123 -> 605
A36: Л.СТ-1.5 | B36: Шкаф высокий широкий (4 низкие двери ЛДСП) | C36: 778*410*1980 | D36: 13227 | E36: =D36*$G$3 -> 18120.99 | F36: ЦБ-00013112 | I36: =A23 -> Л.СТ-1 | J36: =B23 -> Стеллаж высокий широкий | K36: =C23 -> 778*410*1980 | L36: 1 | M36: =D23 -> 8199 | O36: =A117 -> Л.Д-3 (L) | P36: =B117 -> Дверь низкая ЛДСП (для Л.СТ-1, Л.СУ-1, Л.СТ-2, Л.СТ-3, Л.СУ-2, Л.СУ-3) | Q36: =C117 -> 361*764x18 | R36: 2 | S36: =D117 -> 1257 | U36: =A118 -> Л.Д-3 (R) | V36: =B118 -> Дверь низкая ЛДСП (для Л.СТ-1, Л.СУ-1, Л.СТ-2, Л.СТ-3, Л.СУ-2, Л.СУ-3) | W36: =C118 -> 361*764x18 | X36: 2 | Y36: =D118 -> 1257
A37: Л.СТ-1.6 | B37: Шкаф высокий широкий (2 средние двери ЛДСП) | C37: 778*410*1980 | D37: 11237 | E37: =D37*$G$3 -> 15394.69 | F37: ЦБ-00013113 | I37: =A23 -> Л.СТ-1 | J37: =B23 -> Стеллаж высокий широкий | K37: =C23 -> 778*410*1980 | L37: 1 | M37: =D23 -> 8199 | O37: =A115 -> Л.Д-2 (L) | P37: =B115 -> Дверь средняя ЛДСП (для Л.СТ-1, Л.СУ-1, Л.СТ-2, Л.СУ-2) | Q37: =C115 -> 361*1151x18 | R37: 1 | S37: =D115 -> 1519 | U37: =A116 -> Л.Д-2 (R) | V37: =B116 -> Дверь средняя ЛДСП (для Л.СТ-1, Л.СУ-1, Л.СТ-2, Л.СУ-2) | W37: =C116 -> 361*1151x18 | X37: 1 | Y37: =D116 -> 1519
A38: Л.СТ-1.7 | B38: Шкаф высокий широкий (2 средние двери ЛДСП, 2 низкие двери стекло) | C38: 778*410*1980 | D38: 15347 | E38: =D38*$G$3 -> 21025.39 | F38: ЦБ-00013114 | I38: =A23 -> Л.СТ-1 | J38: =B23 -> Стеллаж высокий широкий | K38: =C23 -> 778*410*1980 | L38: 1 | M38: =D23 -> 8199 | O38: =A115 -> Л.Д-2 (L) | P38: =B115 -> Дверь средняя ЛДСП (для Л.СТ-1, Л.СУ-1, Л.СТ-2, Л.СУ-2) | Q38: =C115 -> 361*1151x18 | R38: 1 | S38: =D115 -> 1519 | U38: =A116 -> Л.Д-2 (R) | V38: =B116 -> Дверь средняя ЛДСП (для Л.СТ-1, Л.СУ-1, Л.СТ-2, Л.СУ-2) | W38: =C116 -> 361*1151x18 | X38: 1 | Y38: =D116 -> 1519 | AA38: =A121 -> Л.С-3 (L) | AB38: =B121 -> Дверь низкая стекло (для Л.СТ-1, Л.СТ-2, Л.СТ-3, Л.СУ-1, Л.СУ-2, Л.СУ-3) | AC38: =C121 -> 361*764x4 | AD38: 1 | AE38: =D121 -> 1450 | AG38: =A122 -> Л.С-3 (R) | AH38: =B122 -> Дверь низкая стекло (для Л.СТ-1, Л.СТ-2, Л.СТ-3, Л.СУ-1, Л.СУ-2, Л.СУ-3) | AI38: =C122 -> 361*764x4 | AJ38: 1 | AK38: =D122 -> 1450 | AM38: =AM35 -> Для Л.С-2 | AN38: =AN35 -> Комплект фурнитуры для одного стекла | AO38: =AO35 -> 0 | AP38: =AP35 -> 2 | AQ38: =AQ35 -> 605
A39: Л.СТ-1.8 | B39: Шкаф высокий широкий (2 средние двери ЛДСП, 2 низкие двери ЛДСП) | C39: 778*410*1980 | D39: 13751 | E39: =D39*$G$3 -> 18838.87 | F39: ЦБ-00013115 | I39: =A23 -> Л.СТ-1 | J39: =B23 -> Стеллаж высокий широкий | K39: =C23 -> 778*410*1980 | L39: 1 | M39: =D23 -> 8199 | O39: =A115 -> Л.Д-2 (L) | P39: =B115 -> Дверь средняя ЛДСП (для Л.СТ-1, Л.СУ-1, Л.СТ-2, Л.СУ-2) | Q39: =C115 -> 361*1151x18 | R39: 1 | S39: =D116 -> 1519 | U39: =A116 -> Л.Д-2 (R) | V39: =B116 -> Дверь средняя ЛДСП (для Л.СТ-1, Л.СУ-1, Л.СТ-2, Л.СУ-2) | W39: =C116 -> 361*1151x18 | X39: 1 | Y39: =D116 -> 1519 | AA39: =A117 -> Л.Д-3 (L) | AB39: =B117 -> Дверь низкая ЛДСП (для Л.СТ-1, Л.СУ-1, Л.СТ-2, Л.СТ-3, Л.СУ-2, Л.СУ-3) | AC39: =C117 -> 361*764x18 | AD39: 1 | AE39: =D117 -> 1257 | AG39: =A118 -> Л.Д-3 (R) | AH39: =B118 -> Дверь низкая ЛДСП (для Л.СТ-1, Л.СУ-1, Л.СТ-2, Л.СТ-3, Л.СУ-2, Л.СУ-3) | AI39: =C118 -> 361*764x18 | AJ39: 1 | AK39: =D118 -> 1257
A40: Л.СТ-1.9 | B40: Шкаф высокий широкий (2 высокие двери ЛДСП) | C40: 778*410*1980 | D40: 12675 | E40: =D40*$G$3 -> 17364.75 | F40: ЦБ-00013116 | I40: =A23 -> Л.СТ-1 | J40: =B23 -> Стеллаж высокий широкий | K40: =C23 -> 778*410*1980 | L40: 1 | M40: =D23 -> 8199 | O40: =A113 -> Л.Д-1 (L) | P40: =B113 -> Дверь высокая ЛДСП левая/правая (для Л.ГБ-2, Л.СТ-1, Л.СУ-1 и Л.ГБ-4) | Q40: =C113 -> 361*1916x18 | R40: 1 | S40: =D113 -> 2238 | U40: =A114 -> Л.Д-1 (R) | V40: =B114 -> Дверь высокая ЛДСП левая/правая (для Л.ГБ-2, Л.СТ-1, Л.СУ-1 и Л.ГБ-4) | W40: =C114 -> 361*1916x18 | X40: 1 | Y40: =D114 -> 2238
A41: Л.ШК-1 Т | B41: Шкаф-купе высокий (наполнение - полки) | C41: 1200*410*1980 | D41: 32109 | E41: =D41*$G$3 -> 43989.33 | F41: ЦБ-00068054 | I41: =A160 -> ЛШК-1 Т 1/2 | J41: =B160 -> Каркас | K41: =C160 -> 1200*410*1975 | L41: 1 | M41: =D160 -> 22548 | O41: =A161 -> ЛШК-1 Т 2/2 | P41: =B161 -> Двери зад. стенка | Q41: =C161 -> 1200*410*1975 | R41: 1 | S41: =D161 -> 9561
...
